2024-09-26 09:53:09,187 - __main__ - ERROR - Uncaught exception
Traceback (most recent call last):
  File "script_final_beta.py", line 396, in update_webdriver
  File "pprint.py", line 53, in pprint
  File "pprint.py", line 139, in pprint
  File "pprint.py", line 176, in _format
AttributeError: 'NoneType' object has no attribute 'write'
2024-09-26 09:58:47,539 - __main__ - ERROR - Uncaught exception
Traceback (most recent call last):
  File "script_final_beta.py", line 396, in update_webdriver
  File "pprint.py", line 53, in pprint
  File "pprint.py", line 139, in pprint
  File "pprint.py", line 176, in _format
AttributeError: 'NoneType' object has no attribute 'write'
2024-09-26 09:58:51,246 - __main__ - ERROR - Uncaught exception
Traceback (most recent call last):
  File "script_final_beta.py", line 396, in update_webdriver
  File "pprint.py", line 53, in pprint
  File "pprint.py", line 139, in pprint
  File "pprint.py", line 176, in _format
AttributeError: 'NoneType' object has no attribute 'write'
2024-09-26 10:05:01,035 - __main__ - ERROR - Uncaught exception
Traceback (most recent call last):
  File "script_final_beta.py", line 396, in update_webdriver
  File "pprint.py", line 53, in pprint
  File "pprint.py", line 139, in pprint
  File "pprint.py", line 176, in _format
AttributeError: 'NoneType' object has no attribute 'write'
2024-09-26 10:05:05,127 - __main__ - ERROR - Uncaught exception
Traceback (most recent call last):
  File "script_final_beta.py", line 396, in update_webdriver
  File "pprint.py", line 53, in pprint
  File "pprint.py", line 139, in pprint
  File "pprint.py", line 176, in _format
AttributeError: 'NoneType' object has no attribute 'write'
2024-09-26 10:10:00,099 - __main__ - ERROR - Uncaught exception
Traceback (most recent call last):
  File "script_final_beta.py", line 399, in update_webdriver
  File "pprint.py", line 53, in pprint
  File "pprint.py", line 139, in pprint
  File "pprint.py", line 176, in _format
AttributeError: 'NoneType' object has no attribute 'write'
2024-09-26 10:10:01,495 - __main__ - ERROR - Uncaught exception
Traceback (most recent call last):
  File "script_final_beta.py", line 399, in update_webdriver
  File "pprint.py", line 53, in pprint
  File "pprint.py", line 139, in pprint
  File "pprint.py", line 176, in _format
AttributeError: 'NoneType' object has no attribute 'write'
2024-09-26 10:10:04,194 - __main__ - ERROR - Uncaught exception
Traceback (most recent call last):
  File "script_final_beta.py", line 399, in update_webdriver
  File "pprint.py", line 53, in pprint
  File "pprint.py", line 139, in pprint
  File "pprint.py", line 176, in _format
AttributeError: 'NoneType' object has no attribute 'write'
